2018-12-14 10:06:31,621 ERROR: Exception on / [GET] [in /Users/evh111/Desktop/programz/petblog/myenv/lib/python3.7/site-packages/flask/app.py:1761]
Traceback (most recent call last):
  File "/Users/evh111/Desktop/programz/petblog/myenv/lib/python3.7/site-packages/flask/app.py", line 2292, in wsgi_app
    response = self.full_dispatch_request()
  File "/Users/evh111/Desktop/programz/petblog/myenv/lib/python3.7/site-packages/flask/app.py", line 1815, in full_dispatch_request
    rv = self.handle_user_exception(e)
  File "/Users/evh111/Desktop/programz/petblog/myenv/lib/python3.7/site-packages/flask/app.py", line 1718, in handle_user_exception
    reraise(exc_type, exc_value, tb)
  File "/Users/evh111/Desktop/programz/petblog/myenv/lib/python3.7/site-packages/flask/_compat.py", line 35, in reraise
    raise value
  File "/Users/evh111/Desktop/programz/petblog/myenv/lib/python3.7/site-packages/flask/app.py", line 1813, in full_dispatch_request
    rv = self.dispatch_request()
  File "/Users/evh111/Desktop/programz/petblog/myenv/lib/python3.7/site-packages/flask/app.py", line 1799, in dispatch_request
    return self.view_functions[rule.endpoint](**req.view_args)
  File "/Users/evh111/Desktop/programz/petblog/myenv/lib/python3.7/site-packages/flask_login/utils.py", line 261, in decorated_view
    return func(*args, **kwargs)
  File "/Users/evh111/Desktop/programz/petblog/app/main/routes.py", line 33, in index
    return render_template('index.html', title=_('Home'), form=form,
NameError: name 'form' is not defined
2018-12-14 10:07:00,352 INFO: PetBlog [in /Users/evh111/Desktop/programz/petblog/app/__init__.py:82]
2018-12-14 10:08:58,463 INFO: PetBlog [in /Users/evh111/Desktop/programz/petblog/app/__init__.py:82]
2018-12-14 10:28:45,092 INFO: PetBlog [in /Users/evh111/Desktop/programz/petblog/app/__init__.py:82]
2018-12-14 10:30:18,611 INFO: PetBlog [in /Users/evh111/Desktop/programz/petblog/app/__init__.py:82]
2018-12-14 10:30:41,489 INFO: PetBlog [in /Users/evh111/Desktop/programz/petblog/app/__init__.py:82]
2018-12-14 11:35:01,512 INFO: PetBlog [in /Users/evh111/Desktop/programz/petblog/app/__init__.py:82]
2018-12-14 11:38:52,489 INFO: PetBlog [in /Users/evh111/Desktop/programz/petblog/app/__init__.py:82]
2018-12-14 12:34:12,822 INFO: PetBlog [in /Users/evh111/Desktop/programz/petblog/app/__init__.py:82]
2018-12-14 12:44:01,839 INFO: PetBlog [in /Users/evh111/Desktop/programz/petblog/app/__init__.py:82]
2018-12-14 14:47:43,429 INFO: PetBlog [in /Users/evh111/Desktop/programz/petblog/app/__init__.py:82]
2018-12-14 14:50:45,460 INFO: PetBlog [in /Users/evh111/Desktop/programz/petblog/app/__init__.py:82]
2018-12-14 14:53:03,536 INFO: PetBlog [in /Users/evh111/Desktop/programz/petblog/app/__init__.py:82]
2018-12-14 19:08:33,073 INFO: PetBlog [in /Users/evh111/Desktop/programz/petblog/app/__init__.py:82]
2018-12-14 19:12:04,059 INFO: PetBlog [in /Users/evh111/Desktop/programz/petblog/app/__init__.py:82]
2018-12-14 19:14:08,617 INFO: PetBlog [in /Users/evh111/Desktop/programz/petblog/app/__init__.py:82]
2018-12-14 19:15:08,426 INFO: PetBlog [in /Users/evh111/Desktop/programz/petblog/app/__init__.py:82]
2018-12-14 19:17:40,152 INFO: PetBlog [in /Users/evh111/Desktop/programz/petblog/app/__init__.py:82]
2018-12-14 19:18:38,221 INFO: PetBlog [in /Users/evh111/Desktop/programz/petblog/app/__init__.py:82]
2018-12-14 19:19:45,467 INFO: PetBlog [in /Users/evh111/Desktop/programz/petblog/app/__init__.py:82]
2018-12-14 19:20:11,343 INFO: PetBlog [in /Users/evh111/Desktop/programz/petblog/app/__init__.py:82]
2018-12-14 19:20:30,925 INFO: PetBlog [in /Users/evh111/Desktop/programz/petblog/app/__init__.py:82]
2018-12-14 19:21:01,959 INFO: PetBlog [in /Users/evh111/Desktop/programz/petblog/app/__init__.py:82]
2018-12-14 19:21:40,326 INFO: PetBlog [in /Users/evh111/Desktop/programz/petblog/app/__init__.py:82]
2018-12-14 19:22:23,486 INFO: PetBlog [in /Users/evh111/Desktop/programz/petblog/app/__init__.py:82]
2018-12-14 19:23:00,183 INFO: PetBlog [in /Users/evh111/Desktop/programz/petblog/app/__init__.py:82]
2018-12-17 08:51:27,164 INFO: PetBlog [in /Users/evh111/Desktop/programz/petblog/app/__init__.py:82]
2018-12-17 08:52:47,487 INFO: PetBlog [in /Users/evh111/Desktop/programz/petblog/app/__init__.py:82]
2018-12-21 23:40:28,805 INFO: PetBlog [in /Users/evh111/Desktop/programz/petblog/app/__init__.py:82]
2018-12-25 16:32:08,367 INFO: PetBlog [in /Users/evh111/Desktop/programz/petblog/app/__init__.py:82]
2019-01-02 13:54:53,776 INFO: PetBlog [in /Users/evh111/Desktop/programz/petblog/app/__init__.py:85]
2019-01-02 13:55:14,417 ERROR: Exception on /api/users/1 [GET] [in /Users/evh111/Desktop/programz/petblog/myenv/lib/python3.7/site-packages/flask/app.py:1761]
Traceback (most recent call last):
  File "/Users/evh111/Desktop/programz/petblog/myenv/lib/python3.7/site-packages/flask/app.py", line 2292, in wsgi_app
    response = self.full_dispatch_request()
  File "/Users/evh111/Desktop/programz/petblog/myenv/lib/python3.7/site-packages/flask/app.py", line 1815, in full_dispatch_request
    rv = self.handle_user_exception(e)
  File "/Users/evh111/Desktop/programz/petblog/myenv/lib/python3.7/site-packages/flask/app.py", line 1718, in handle_user_exception
    reraise(exc_type, exc_value, tb)
  File "/Users/evh111/Desktop/programz/petblog/myenv/lib/python3.7/site-packages/flask/_compat.py", line 35, in reraise
    raise value
  File "/Users/evh111/Desktop/programz/petblog/myenv/lib/python3.7/site-packages/flask/app.py", line 1813, in full_dispatch_request
    rv = self.dispatch_request()
  File "/Users/evh111/Desktop/programz/petblog/myenv/lib/python3.7/site-packages/flask/app.py", line 1799, in dispatch_request
    return self.view_functions[rule.endpoint](**req.view_args)
  File "/Users/evh111/Desktop/programz/petblog/app/api/users.py", line 5, in get_user
    return jsonify(User.query.get_or_404(id).to_dict())  # But it also returns 'None' if no id exists, and aborts the error
NameError: name 'jsonify' is not defined
2019-01-02 13:56:13,092 INFO: PetBlog [in /Users/evh111/Desktop/programz/petblog/app/__init__.py:85]
2019-01-02 13:56:16,419 ERROR: Exception on /api/users/1 [GET] [in /Users/evh111/Desktop/programz/petblog/myenv/lib/python3.7/site-packages/flask/app.py:1761]
Traceback (most recent call last):
  File "/Users/evh111/Desktop/programz/petblog/myenv/lib/python3.7/site-packages/flask/app.py", line 2292, in wsgi_app
    response = self.full_dispatch_request()
  File "/Users/evh111/Desktop/programz/petblog/myenv/lib/python3.7/site-packages/flask/app.py", line 1815, in full_dispatch_request
    rv = self.handle_user_exception(e)
  File "/Users/evh111/Desktop/programz/petblog/myenv/lib/python3.7/site-packages/flask/app.py", line 1718, in handle_user_exception
    reraise(exc_type, exc_value, tb)
  File "/Users/evh111/Desktop/programz/petblog/myenv/lib/python3.7/site-packages/flask/_compat.py", line 35, in reraise
    raise value
  File "/Users/evh111/Desktop/programz/petblog/myenv/lib/python3.7/site-packages/flask/app.py", line 1813, in full_dispatch_request
    rv = self.dispatch_request()
  File "/Users/evh111/Desktop/programz/petblog/myenv/lib/python3.7/site-packages/flask/app.py", line 1799, in dispatch_request
    return self.view_functions[rule.endpoint](**req.view_args)
  File "/Users/evh111/Desktop/programz/petblog/app/api/users.py", line 7, in get_user
    return jsonify(User.query.get_or_404(id).to_dict())  # But it also returns 'None' if no id exists, and aborts the error
  File "/Users/evh111/Desktop/programz/petblog/app/models.py", line 178, in to_dict
    'post_count': self.post_count(),
AttributeError: 'User' object has no attribute 'post_count'
2019-01-02 13:59:56,499 INFO: PetBlog [in /Users/evh111/Desktop/programz/petblog/app/__init__.py:85]
2019-01-02 14:09:45,220 INFO: PetBlog [in /Users/evh111/Desktop/programz/petblog/app/__init__.py:85]
2019-01-02 15:00:09,926 INFO: PetBlog [in /Users/evh111/Desktop/programz/petblog/app/__init__.py:85]
2019-01-02 15:00:31,650 ERROR: Exception on /api/users [GET] [in /Users/evh111/Desktop/programz/petblog/myenv/lib/python3.7/site-packages/flask/app.py:1761]
Traceback (most recent call last):
  File "/Users/evh111/Desktop/programz/petblog/myenv/lib/python3.7/site-packages/flask/app.py", line 2292, in wsgi_app
    response = self.full_dispatch_request()
  File "/Users/evh111/Desktop/programz/petblog/myenv/lib/python3.7/site-packages/flask/app.py", line 1816, in full_dispatch_request
    return self.finalize_request(rv)
  File "/Users/evh111/Desktop/programz/petblog/myenv/lib/python3.7/site-packages/flask/app.py", line 1831, in finalize_request
    response = self.make_response(rv)
  File "/Users/evh111/Desktop/programz/petblog/myenv/lib/python3.7/site-packages/flask/app.py", line 1957, in make_response
    'The view function did not return a valid response. The'
TypeError: The view function did not return a valid response. The function either returned None or ended without a return statement.
2019-01-03 14:38:16,086 INFO: PetBlog [in /Users/evh111/Desktop/programz/petblog/app/__init__.py:85]
2019-01-03 14:38:59,951 ERROR: Exception on /api/users/1/followed [GET] [in /Users/evh111/Desktop/programz/petblog/myenv/lib/python3.7/site-packages/flask/app.py:1761]
Traceback (most recent call last):
  File "/Users/evh111/Desktop/programz/petblog/myenv/lib/python3.7/site-packages/flask/app.py", line 2292, in wsgi_app
    response = self.full_dispatch_request()
  File "/Users/evh111/Desktop/programz/petblog/myenv/lib/python3.7/site-packages/flask/app.py", line 1816, in full_dispatch_request
    return self.finalize_request(rv)
  File "/Users/evh111/Desktop/programz/petblog/myenv/lib/python3.7/site-packages/flask/app.py", line 1831, in finalize_request
    response = self.make_response(rv)
  File "/Users/evh111/Desktop/programz/petblog/myenv/lib/python3.7/site-packages/flask/app.py", line 1957, in make_response
    'The view function did not return a valid response. The'
TypeError: The view function did not return a valid response. The function either returned None or ended without a return statement.
2019-01-04 14:19:04,052 INFO: PetBlog [in /Users/evh111/Desktop/programz/petblog/app/__init__.py:85]
